2022-04-06 15:18:13,987 - main - INFO - +12047861522 test.pdf +12044799001
2022-04-06 15:20:47,410 - main - INFO - +12047861522 test.pdf +12044799001
2022-04-06 15:26:39,694 - main - INFO - +12047861522 test.pdf +12044799001
2022-04-06 15:38:44,319 - main - INFO - +12047861522 test.pdf +12044799001
2022-04-06 15:49:37,100 - main - INFO - +12047861522 test.pdf +12044799001
2022-04-08 16:22:57,681 - main - INFO - +12047861522 test.pdf +12044799001
2022-04-12 10:35:22,689 - main - INFO - +12047861522 tes2.pdf +12044799001
2022-04-12 10:35:23,224 - main - CRITICAL - Ring Central Exception occurred
Traceback (most recent call last):
  File "E:\pyfaxrc\apps\pyfaxrc.py", line 41, in <module>
    with open(faxdoc, encoding="utf8", errors='ignore') as f:
FileNotFoundError: [Errno 2] No such file or directory: 'tes2.pdf'
2022-04-12 10:35:47,962 - main - INFO - +12047861522 test.pdf +12044799001
2022-04-12 10:35:48,330 - main - CRITICAL - Ring Central Exception occurred
Traceback (most recent call last):
  File "E:\pyfaxrc\apps\pyfaxrc.py", line 41, in <module>
    with open(faxdoc, encoding="utf8", errors='ignore') as f:
FileNotFoundError: [Errno 2] No such file or directory: 'test.pdf'
2022-04-12 10:36:40,236 - main - INFO - +12047861522 test.pdf +12044799001
2022-04-12 10:36:40,638 - main - CRITICAL - Ring Central Exception occurred
Traceback (most recent call last):
  File "E:\pyfaxrc\apps\pyfaxrc.py", line 41, in <module>
    with open(faxdoc, encoding="utf8", errors='ignore') as f:
FileNotFoundError: [Errno 2] No such file or directory: 'test.pdf'
2022-04-12 11:05:06,079 - main - INFO - +12047861522 E:\pyfaxrc\apps\Outbound\test.pdf +12044799001
2022-04-12 11:28:06,346 - main - INFO - +12047861522 test.pdf +12044799001
2022-04-12 11:28:06,346 - main - ERROR - Document not found test.pdf
2022-04-12 11:28:06,346 - main - ERROR - Fax document has invalid extension
NoneType: None
