2022-04-13 22:25:36,726 - main - INFO - +12047861522 test.pdf +12044799001
2022-04-13 22:25:36,742 - main - CRITICAL - Ring Central Exception occurred
Traceback (most recent call last):
  File "E:\pyfaxrc\apps\pyfaxrc.py", line 37, in <module>
    platform.login(jwt=JWT_TOKEN)
  File "E:\pyfaxrc\.venv\lib\site-packages\ringcentral\platform\platform.py", line 123, in login
    raise e
  File "E:\pyfaxrc\.venv\lib\site-packages\ringcentral\platform\platform.py", line 117, in login
    response = self._request_token(TOKEN_ENDPOINT, body=body)
  File "E:\pyfaxrc\.venv\lib\site-packages\ringcentral\platform\platform.py", line 186, in _request_token
    'Authorization': 'Basic ' + self._api_key(),
  File "E:\pyfaxrc\.venv\lib\site-packages\ringcentral\platform\platform.py", line 193, in _api_key
    return base64encode(self._key + ':' + self._secret)
TypeError: can only concatenate list (not "str") to list
2022-04-13 22:26:56,007 - main - INFO - +12047861522 test.pdf +12044799001
2022-04-13 22:26:56,007 - main - CRITICAL - Ring Central Exception occurred
Traceback (most recent call last):
  File "E:\pyfaxrc\apps\pyfaxrc.py", line 37, in <module>
    platform.login(jwt=JWT_TOKEN)
  File "E:\pyfaxrc\.venv\lib\site-packages\ringcentral\platform\platform.py", line 123, in login
    raise e
  File "E:\pyfaxrc\.venv\lib\site-packages\ringcentral\platform\platform.py", line 117, in login
    response = self._request_token(TOKEN_ENDPOINT, body=body)
  File "E:\pyfaxrc\.venv\lib\site-packages\ringcentral\platform\platform.py", line 186, in _request_token
    'Authorization': 'Basic ' + self._api_key(),
  File "E:\pyfaxrc\.venv\lib\site-packages\ringcentral\platform\platform.py", line 193, in _api_key
    return base64encode(self._key + ':' + self._secret)
TypeError: can only concatenate list (not "str") to list
2022-04-13 22:27:47,500 - main - INFO - +12047861522 test.pdf +12044799001
2022-04-13 22:27:47,500 - main - CRITICAL - Ring Central Exception occurred
Traceback (most recent call last):
  File "E:\pyfaxrc\apps\pyfaxrc.py", line 32, in <module>
    JWT_TOKEN = [RC_JWT]
NameError: name 'RC_JWT' is not defined
2022-04-13 22:28:49,615 - main - INFO - +12047861522 test.pdf +12044799001
2022-04-13 22:28:49,615 - main - CRITICAL - Ring Central Exception occurred
Traceback (most recent call last):
  File "E:\pyfaxrc\apps\pyfaxrc.py", line 37, in <module>
    platform.login(jwt=JWT_TOKEN)
  File "E:\pyfaxrc\.venv\lib\site-packages\ringcentral\platform\platform.py", line 123, in login
    raise e
  File "E:\pyfaxrc\.venv\lib\site-packages\ringcentral\platform\platform.py", line 117, in login
    response = self._request_token(TOKEN_ENDPOINT, body=body)
  File "E:\pyfaxrc\.venv\lib\site-packages\ringcentral\platform\platform.py", line 186, in _request_token
    'Authorization': 'Basic ' + self._api_key(),
  File "E:\pyfaxrc\.venv\lib\site-packages\ringcentral\platform\platform.py", line 193, in _api_key
    return base64encode(self._key + ':' + self._secret)
TypeError: can only concatenate list (not "str") to list
2022-04-13 22:35:09,522 - main - INFO - +12047861522 test.pdf +12044799001
2022-04-13 22:35:09,522 - urllib3.connectionpool - DEBUG - Starting new HTTPS connection (1): platform.devtest.ringcentral.com:443
2022-04-13 22:35:10,377 - urllib3.connectionpool - DEBUG - https://platform.devtest.ringcentral.com:443 "POST /restapi/oauth/token HTTP/1.1" 200 946
2022-04-13 22:35:10,377 - main - CRITICAL - Ring Central Exception occurred
Traceback (most recent call last):
  File "E:\pyfaxrc\apps\pyfaxrc.py", line 46, in <module>
    with open(faxdoc, encoding="utf8", errors='ignore') as f:
FileNotFoundError: [Errno 2] No such file or directory: 'E:\\pyfaxrc\\apps\\outbound\\test.pdf'
2022-04-13 22:36:04,892 - main - INFO - +12047861522 test.pdf +12044799001
2022-04-13 22:36:04,892 - urllib3.connectionpool - DEBUG - Starting new HTTPS connection (1): platform.devtest.ringcentral.com:443
2022-04-13 22:36:05,268 - urllib3.connectionpool - DEBUG - https://platform.devtest.ringcentral.com:443 "POST /restapi/oauth/token HTTP/1.1" 200 946
2022-04-13 22:36:05,268 - main - CRITICAL - Ring Central Exception occurred
Traceback (most recent call last):
  File "E:\pyfaxrc\apps\pyfaxrc.py", line 57, in <module>
    j_resp = '_' + recipient + '_' + os.path.basename(faxdoc) + '_' + resp.json().messageStatus
NameError: name 'resp' is not defined
2022-04-13 22:36:56,986 - main - INFO - +12047861522 test.pdf +12044799001
2022-04-13 22:36:56,986 - urllib3.connectionpool - DEBUG - Starting new HTTPS connection (1): platform.devtest.ringcentral.com:443
2022-04-13 22:36:57,345 - urllib3.connectionpool - DEBUG - https://platform.devtest.ringcentral.com:443 "POST /restapi/oauth/token HTTP/1.1" 200 946
2022-04-13 22:36:57,345 - urllib3.connectionpool - DEBUG - Starting new HTTPS connection (1): platform.devtest.ringcentral.com:443
2022-04-13 22:36:57,924 - urllib3.connectionpool - DEBUG - https://platform.devtest.ringcentral.com:443 "POST /restapi/v1.0/account/~/extension/~/fax HTTP/1.1" 200 890
2022-04-13 22:36:57,924 - root - INFO - __+12047861522__test.pdf
